Workbook

Sheet Summary
B1: Tab Name | C1: Description
B2: Function Tracker | C2: This is where you can keep track of the functions we are learning as we go along. Feel read the definitions of some of the later functions!
B3: Shortcuts | C3: This sheet will follow you to all our spreadsheet sections. This is a reference sheet in case you forget some of the many shortcuts that exist in Google sheets!
B4: Lecture One: What is a Spreadsheet | C4: What is a spreasheet? This tab will provide you with definitions of some basic spreasheet terminology. No need to refer to this after lecture one.
B5: Lecture Two: Data Types | C5: Learn about data types in Google Spreadsheet!
B6: Lecture Three: Navigating Spreadsheets | C6: This tab provides you with a list of my favorite shortcuts, as well as some data to try out some shortcuts on. I nested some interseting challenges to activate your imagination for spreadsheets.
A15: Copyright: SanSone Partners

Sheet Function Tracker
A1: =IFERROR(__xludf.DUMMYFUNCTION("QUERY($W:$Y,""SELECT * WHERE W <= ""&E2&"""",-1)"),"Index") -> Index | B1: =IFERROR(__xludf.DUMMYFUNCTION("""COMPUTED_VALUE"""),"Function") -> Function | C1: =IFERROR(__xludf.DUMMYFUNCTION("""COMPUTED_VALUE"""),"Description") -> Description | E1: Counter | W1: Index | X1: Function | Y1: Description
A2: =IFERROR(__xludf.DUMMYFUNCTION("""COMPUTED_VALUE"""),1.0) -> 1 | B2: =IFERROR(__xludf.DUMMYFUNCTION("""COMPUTED_VALUE"""),"SUM") -> SUM | C2: =IFERROR(__xludf.DUMMYFUNCTION("""COMPUTED_VALUE"""),"Returns the sum of a series of numbers and/or cells.") -> Returns the sum of a series of numbers and/or cells. | E2: 1 | V2: Numbers | W2: 1 | X2: SUM | Y2: Returns the sum of a series of numbers and/or cells.
V3: Numbers | W3: 2 | X3: AVERAGE | Y3: Returns the numerical average value in a dataset, ignoring text.
V4: Numbers | W4: 3 | X4: PRODUCT | Y4: Returns the result of multiplying a series of numbers together.
V5: Numbers | W5: 4 | X5: QUOTIENT | Y5: Returns one number divided by another.
V6: Numbers | W6: 5 | X6: COUNT | Y6: Returns a count of the number of numeric values in a dataset.
V7: Numbers | W7: 6 | X7: MIN | Y7: Returns the minimum value in a numeric dataset.
V8: Numbers | W8: 7 | X8: MAX | Y8: Returns the maximum value in a numeric dataset.
V9: Numbers | W9: 8 | X9: IF | Y9: Returns one value if a logical expression is `TRUE` and another if it is `FALSE`.
V10: Numbers | W10: 9 | X10: OR | Y10: Returns a conditional sum across a range.
V11: Numbers | W11: 10 | X11: AND | Y11: Returns the sum of a range depending on multiple criteria.
V12: Numbers | W12: 11 | X12: SUMIF | Y12: Returns the average of a range depending on criteria.
V13: Numbers | W13: 12 | X13: SUMIFS | Y13: Returns the average of a range depending on multiple criteria.
V14: Numbers | W14: 13 | X14: AVERAGEIF | Y14: Returns the minimum value in a range of cells, filtered by a set of criteria.
... V54: Misc | W54: 53 | X54: IMPORTRANGE | Y54: Creates a hyperlink inside a cell.

Sheet Shortcuts
A1: Google Sheets Shortcuts!
D2: COMPUTER TYPE | E2: Shortcut Resources!
A3: Command to Search ---> | B3: Apply top border | C3: {=IF(D3="Mac", IFERROR(INDEX($A$5:$B$160,MATCH(B3,$A$5:$A$160,0),2),"<--- Enter your Search"),IF(D3="PC",IFERROR(INDEX($A$5:$C$160,MATCH(B3,$A$5:$A$160,0),3),"<--- Enter your Search")))} -> Alt + Shift + 1 | D3: PC | E3: =HYPERLINK("https://support.google.com/docs/answer/181110?co=GENIE.Platform%3DDesktop&hl=en","Google Sheets Shortcuts") -> Google Sheets Shortcuts
E4: =HYPERLINK("https://exceljet.net/keyboard-shortcuts","Excel Shortcuts") -> Excel Shortcuts
E5: =HYPERLINK("https://docs.google.com/document/d/1y4DFaqHzEBBY5N0PRsqu2Gxas1kw9iJzA7PzOPekrEE/edit#","Printable Shortcuts Page") -> Printable Shortcuts Page
A6: Command Description | B6: Mac | C6: PC
A7: Show common keyboard shortcuts | B7: ⌘ + / | C7: =INDEX($A$43:$D$159,MATCH(A7,$A$43:$A$159,0),3) -> Ctrl + /
A8: Move to beginning of sheet | B8: ⌘ + Fn + Left arrow | C8: =INDEX($A$43:$D$159,MATCH(A8,$A$43:$A$159,0),3) -> Ctrl + Home
A9: Move to end of row | B9: ⌘ + Directional Arrows | C9: =INDEX($A$43:$D$159,MATCH(A9,$A$43:$A$159,0),3) -> End
A10: Move to next sheet | B10: ⌘ + Shift + Fn + Down arrow | C10: =INDEX($A$43:$D$159,MATCH(A10,$A$43:$A$159,0),3) -> Ctrl + Shift + Page Down
A11: Move to previous sheet | B11: ⌘ + Shift + Fn + Up arrow | C11: =INDEX($A$43:$D$159,MATCH(A11,$A$43:$A$159,0),3) -> Ctrl + Shift + Page Up
A12: Fill down | B12: ⌘ + d | C12: =INDEX($A$43:$D$159,MATCH(A12,$A$43:$A$159,0),3) -> Ctrl + d
A13: Fill right | B13: ⌘ + r | C13: =INDEX($A$43:$D$159,MATCH(A13,$A$43:$A$159,0),3) -> Ctrl + r
A14: Paste | B14: ⌘ + v | C14: =INDEX($A$43:$D$159,MATCH(A14,$A$43:$A$159,0),3) -> Ctrl + v
A15: Paste values only | B15: ⌘ + Shift + v | C15: =INDEX($A$43:$D$159,MATCH(A15,$A$43:$A$159,0),3) -> Ctrl + Shift + v
A16: Paste format only | B16: ⌘ + Option + v | C16: Ctrl + Alt + v
A17: Find | B17: ⌘ + f | C17: =INDEX($A$43:$D$159,MATCH(A17,$A$43:$A$159,0),3) -> Ctrl + f
A18: Find and replace | B18: ⌘ + Shift + h | C18: =INDEX($A$43:$D$159,MATCH(A18,$A$43:$A$159,0),3) -> Ctrl + h
A19: Undo | B19: ⌘ + z | C19: =INDEX($A$43:$D$159,MATCH(A19,$A$43:$A$159,0),3) -> Ctrl + z
A20: Redo | B20: ⌘ + y ⌘ + Shift + z Fn + F4 | C20: =INDEX($A$43:$D$159,MATCH(A20,$A$43:$A$159,0),3) -> Ctrl + y Ctrl + Shift + z F4
A21: Bold | B21: ⌘ + b | C21: =INDEX($A$43:$D$159,MATCH(A21,$A$43:$A$159,0),3) -> Ctrl + b
A22: Center align | B22: ⌘ + Shift + e | C22: =INDEX($A$43:$D$159,MATCH(A22,$A$43:$A$159,0),3) -> Ctrl + Shift + e
A23: Left align | B23: ⌘ + Shift + l | C23: =INDEX($A$43:$D$159,MATCH(A23,$A$43:$A$159,0),3) -> Ctrl + Shift + l
A24: Right align | B24: ⌘ + Shift + r | C24: =INDEX($A$43:$D$159,MATCH(A24,$A$43:$A$159,0),3) -> Ctrl + Shift + r
A25: Apply bottom border | B25: Option + Shift + 3 | C25: =INDEX($A$43:$D$159,MATCH(A25,$A$43:$A$159,0),3) -> Alt + Shift + 3
A26: Apply outer border | B26: Option + Shift + 7 ⌘ + Shift + 7 | C26: =INDEX($A$43:$D$159,MATCH(A26,$A$43:$A$159,0),3) -> Alt + Shift + 7 Ctrl + Shift + 7
A27: Remove borders | B27: Option + Shift + 6 | C27: =INDEX($A$43:$D$159,MATCH(A27,$A$43:$A$159,0),3) -> Alt + Shift + 6
A28: Insert link | B28: ⌘ + k | C28: =INDEX($A$43:$D$159,MATCH(A28,$A$43:$A$159,0),3) -> Ctrl + k
... A37: Ungroup rows or columns | B37: Option + Shift + Left arrow | C37: =INDEX($A$43:$D$159,MATCH(A37,$A$43:$A$159,0),3) -> Ctrl + Shift + 0
A42: Mac | C42: PC
A43: Common actions
A44: Select column | B44: Ctrl + Space | C44: Ctrl + Space
A45: Select row | B45: Shift + Space | C45: Shift + Space
A46: Select all | B46: ⌘ + a ⌘ + Shift + Space | C46: Ctrl + a Ctrl + Shift + Space
A47: Undo | B47: ⌘ + z | C47: Ctrl + z
A48: Redo | B48: ⌘ + y ⌘ + Shift + z Fn + F4 | C48: Ctrl + y Ctrl + Shift + z F4
A49: Find | B49: ⌘ + f | C49: Ctrl + f
A50: Find and replace | B50: ⌘ + Shift + h | C50: Ctrl + h
A51: Fill range | B51: ⌘ + Enter | C51: Ctrl + Enter
A52: Fill down | B52: ⌘ + d | C52: Ctrl + d
...

Sheet Section One ----->

Sheet Lecture One What is a Spreadshe
A1: Cells
B2: Cell B2
L5: Cell L5
G7: Cell G7
A11: Vertical & Horizontal Ranges | B11: Vertical Range B12:B21 | H11: Horizontal Range D12:L12
B12: 16 | D12: 16 | E12: 37 | F12: 43 | G12: 5 | H12: 5 | I12: 8 | J12: 21 | K12: 48
B13: 37
B14: 43
B15: 5
B16: 5
B17: 8
B18: 21
B19: 48
B20: 46
B21: 25
A24: General Ranges | G24: Range B25:L34
B25: 14 | C25: 39 | D25: 6 | E25: 16 | F25: 31 | G25: 13 | H25: 36 | I25: 20 | J25: 16 | K25: 24 | L25: 42
B26: 33 | C26: 22 | D26: 36 | E26: 50 | F26: 39 | G26: 35 | H26: 50 | I26: 49 | J26: 33 | K26: 30 | L26: 46
B27: 7 | C27: 33 | D27: 32 | E27: 20 | F27: 46 | G27: 39 | H27: 23 | I27: 24 | J27: 9 | K27: 4 | L27: 7
B28: 46 | C28: 35 | D28: 24 | E28: 43 | F28: 35 | G28: 11 | H28: 43 | I28: 24 | J28: 14 | K28: 24 | L28: 28
B29: 42 | C29: 21 | D29: 4 | E29: 29 | F29: 39 | G29: 16 | H29: 30 | I29: 31 | J29: 37 | K29: 9 | L29: 39
B30: 21 | C30: 16 | D30: 31 | E30: 16 | F30: 4 | G30: 23 | H30: 23 | I30: 19 | J30: 34 | K30: 12 | L30: 20
B31: 45 | C31: 31 | D31: 43 | E31: 46 | F31: 29 | G31: 23 | H31: 26 | I31: 45 | J31: 25 | K31: 24 | L31: 19
B32: 15 | C32: 9 | D32: 19 | E32: 26 | F32: 49 | G32: 47 | H32: 40 | I32: 21 | J32: 12 | K32: 10 | L32: 46
B33: 4 | C33: 31 | D33: 30 | E33: 33 | F33: 17 | G33: 22 | H33: 39 | I33: 35 | J33: 39 | K33: 40 | L33: 47
B34: 42 | C34: 7 | D34: 25 | E34: 46 | F34: 48 | G34: 38 | H34: 39 | I34: 22 | J34: 20 | K34: 15 | L34: 4

Sheet Lecture Two Data Types
A1: Labels Strings | non-numeric
C2: Names | E2: Quarters | G2: Months
C3: Andrew | E3: Q1 | G3: January
C4: Elvis | E4: Q2 | G4: June
C5: Jimi | E5: Q3 | G5: April
C6: Dave | E6: Q4 | G6: August
A10: Values Numbers | Dates | Currencies
C11: Amount Paid | E11: Quarters | G11: Dates
C12: 100 | E12: 43101 | G12: 43101
C13: 200 | E13: 43191 | G13: 43271 | I13: INPUTS
C14: 400 | E14: 43282 | G14: 43202
C15: 600 | E15: 43374 | G15: 43322
A19: Formulas Combinations of Functions
C21: Formula 1 | E21: Formula 2 | G21: Formula 3
C22: =SUM(C12:C15) -> 1300 | E22: =(G13-G12)*C22 -> 221000 | G22: =PRODUCT(AVERAGE(C12:C15),G14-G12-200) -> -32175

Sheet Lecture Three Navigating Spread
A1: b | H1: Sample Range 1 | M1: Sample Range 2 | O1: Change the range below [O4:O103] to % | P1: Change the range below [P4:P103] to $
K2: Bold the title below! | O2: HINT: (Shift+CTRL+5) | P2: HINT: (Shift +CTRL+4) | R2: Add a Bottom Border!
A3: Evan's Useful Shortcuts! For Reference. | G3: Index | H3: Order | I3: # of Dumplings | K3: Index | L3: Order | M3: # of Dumplings | N3: Cost | O3: Tip | P3: Total | R3: Price per Dumpling
A4: Command Description | B4: Mac | C4: PC | G4: 1 | H4: Order 1 | I4: 7 | K4: 1 | L4: =CONCATENATE("Order ",K4) -> Order 1 | M4: 19 | N4: =M4*$R$4 -> 23.75 | O4: 0.17 | P4: =N4+(N4*O4) -> 27.7875 | R4: 1.25
A5: =Shortcuts!A7 -> Show common keyboard shortcuts | B5: =Shortcuts!B7 -> ⌘ + / | C5: =Shortcuts!C7 -> Ctrl + / | G5: 2 | H5: Order 2 | I5: 6 | K5: =K4+1 -> 2 | L5: =CONCATENATE("Order ",K5) -> Order 2 | M5: 13 | N5: =M5*$R$4 -> 16.25 | O5: 0.18 | P5: =N5+(N5*O5) -> 19.175
A6: =Shortcuts!A8 -> Move to beginning of sheet | B6: =Shortcuts!B8 -> ⌘ + Fn + Left arrow | C6: =Shortcuts!C8 -> Ctrl + Home | G6: 3 | H6: Order 3 | I6: 8 | K6: =K5+1 -> 3 | L6: =CONCATENATE("Order ",K6) -> Order 3 | M6: 19 | N6: =M6*$R$4 -> 23.75 | O6: 0.15 | P6: =N6+(N6*O6) -> 27.3125
A7: =Shortcuts!A9 -> Move to end of row | B7: =Shortcuts!B9 -> ⌘ + Directional Arrows | C7: =Shortcuts!C9 -> End | G7: 4 | H7: Order 4 | I7: 5 | K7: =K6+1 -> 4 | L7: =CONCATENATE("Order ",K7) -> Order 4 | M7: 18 | N7: =M7*$R$4 -> 22.5 | O7: 0.18 | P7: =N7+(N7*O7) -> 26.55
A8: =Shortcuts!A10 -> Move to next sheet | B8: =Shortcuts!B10 -> ⌘ + Shift + Fn + Down arrow | C8: =Shortcuts!C10 -> Ctrl + Shift + Page Down | G8: 5 | H8: Order 5 | I8: 6 | K8: =K7+1 -> 5 | L8: =CONCATENATE("Order ",K8) -> Order 5 | M8: 16 | N8: =M8*$R$4 -> 20 | O8: 0.18 | P8: =N8+(N8*O8) -> 23.6
A9: =Shortcuts!A11 -> Move to previous sheet | B9: =Shortcuts!B11 -> ⌘ + Shift + Fn + Up arrow | C9: =Shortcuts!C11 -> Ctrl + Shift + Page Up | G9: 6 | H9: Order 6 | I9: 7 | K9: =K8+1 -> 6 | L9: =CONCATENATE("Order ",K9) -> Order 6 | M9: 18 | N9: =M9*$R$4 -> 22.5 | O9: 0.15 | P9: =N9+(N9*O9) -> 25.875
A10: =Shortcuts!A12 -> Fill down | B10: =Shortcuts!B12 -> ⌘ + d | C10: =Shortcuts!C12 -> Ctrl + d | G10: 7 | H10: Order 7 | I10: 6 | K10: =K9+1 -> 7 | L10: =CONCATENATE("Order ",K10) -> Order 7 | M10: 13 | N10: =M10*$R$4 -> 16.25 | O10: 0.18 | P10: =N10+(N10*O10) -> 19.175
A11: =Shortcuts!A13 -> Fill right | B11: =Shortcuts!B13 -> ⌘ + r | C11: =Shortcuts!C13 -> Ctrl + r | G11: 8 | H11: Order 8 | I11: 9 | K11: =K10+1 -> 8 | L11: =CONCATENATE("Order ",K11) -> Order 8 | M11: 12 | N11: =M11*$R$4 -> 15 | O11: 0.18 | P11: =N11+(N11*O11) -> 17.7
A12: =Shortcuts!A14 -> Paste | B12: =Shortcuts!B14 -> ⌘ + v | C12: =Shortcuts!C14 -> Ctrl + v | G12: 9 | H12: Order 9 | I12: 5 | K12: =K11+1 -> 9 | L12: =CONCATENATE("Order ",K12) -> Order 9 | M12: 7 | N12: =M12*$R$4 -> 8.75 | O12: 0.15 | P12: =N12+(N12*O12) -> 10.0625
A13: =Shortcuts!A15 -> Paste values only | B13: =Shortcuts!B15 -> ⌘ + Shift + v | C13: =Shortcuts!C15 -> Ctrl + Shift + v | G13: 10 | H13: Order 10 | I13: 9 | K13: =K12+1 -> 10 | L13: =CONCATENATE("Order ",K13) -> Order 10 | M13: 8 | N13: =M13*$R$4 -> 10 | O13: 0.15 | P13: =N13+(N13*O13) -> 11.5
A14: =Shortcuts!A16 -> Paste format only | B14: =Shortcuts!B16 -> ⌘ + Option + v | C14: =Shortcuts!C16 -> Ctrl + Alt + v | G14: 11 | H14: =CONCATENATE("Order ",G14) -> Order 11 | I14: 12 | K14: =K13+1 -> 11 | L14: =CONCATENATE("Order ",K14) -> Order 11 | M14: 7 | N14: =M14*$R$4 -> 8.75 | O14: 0.15 | P14: =N14+(N14*O14) -> 10.0625
A15: =Shortcuts!A17 -> Find | B15: =Shortcuts!B17 -> ⌘ + f | C15: =Shortcuts!C17 -> Ctrl + f | G15: 12 | H15: =CONCATENATE("Order ",G15) -> Order 12 | I15: 7 | K15: =K14+1 -> 12 | L15: =CONCATENATE("Order ",K15) -> Order 12 | M15: 5 | N15: =M15*$R$4 -> 6.25 | O15: 0.15 | P15: =N15+(N15*O15) -> 7.1875
A16: =Shortcuts!A18 -> Find and replace | B16: =Shortcuts!B18 -> ⌘ + Shift + h | C16: =Shortcuts!C18 -> Ctrl + h | F16: Try cut and pasting the | G16: 13 | H16: =CONCATENATE("Order ",G16) -> Order 13 | I16: 12 | K16: =K15+1 -> 13 | L16: =CONCATENATE("Order ",K16) -> Order 13 | M16: 13 | N16: =M16*$R$4 -> 16.25 | O16: 0.15 | P16: =N16+(N16*O16) -> 18.6875
A17: =Shortcuts!A19 -> Undo | B17: =Shortcuts!B19 -> ⌘ + z | C17: =Shortcuts!C19 -> Ctrl + z | F17: range on your right into | G17: 14 | H17: =CONCATENATE("Order ",G17) -> Order 14 | I17: 7 | K17: =K16+1 -> 14 | L17: =CONCATENATE("Order ",K17) -> Order 14 | M17: 16 | N17: =M17*$R$4 -> 20 | O17: 0.15 | P17: =N17+(N17*O17) -> 23
A18: =Shortcuts!A20 -> Redo | B18: =left(Shortcuts!B20,5) -> ⌘ + y | C18: =left(Shortcuts!C20,8) -> Ctrl + y | F18: cell G14! | G18: 15 | H18: =CONCATENATE("Order ",G18) -> Order 15 | I18: 10 | K18: =K17+1 -> 15 | L18: =CONCATENATE("Order ",K18) -> Order 15 | M18: 9 | N18: =M18*$R$4 -> 11.25 | O18: 0.15 | P18: =N18+(N18*O18) -> 12.9375
A19: =Shortcuts!A21 -> Bold | B19: =Shortcuts!B21 -> ⌘ + b | C19: =Shortcuts!C21 -> Ctrl + b | G19: 16 | H19: =CONCATENATE("Order ",G19) -> Order 16 | I19: 6 | K19: =K18+1 -> 16 | L19: =CONCATENATE("Order ",K19) -> Order 16 | M19: 18 | N19: =M19*$R$4 -> 22.5 | O19: 0.15 | P19: =N19+(N19*O19) -> 25.875
A20: =Shortcuts!A22 -> Center align | B20: =Shortcuts!B22 -> ⌘ + Shift + e | C20: =Shortcuts!C22 -> Ctrl + Shift + e | G20: 17 | H20: =CONCATENATE("Order ",G20) -> Order 17 | I20: 8 | K20: =K19+1 -> 17 | L20: =CONCATENATE("Order ",K20) -> Order 17 | M20: 14 | N20: =M20*$R$4 -> 17.5 | O20: 0.18 | P20: =N20+(N20*O20) -> 20.65
A21: =Shortcuts!A23 -> Left align | B21: =Shortcuts!B23 -> ⌘ + Shift + l | C21: =Shortcuts!C23 -> Ctrl + Shift + l | K21: =K20+1 -> 18 | L21: =CONCATENATE("Order ",K21) -> Order 18 | M21: 20 | N21: =M21*$R$4 -> 25 | O21: 0.18 | P21: =N21+(N21*O21) -> 29.5
A22: =Shortcuts!A24 -> Right align | B22: =Shortcuts!B24 -> ⌘ + Shift + r | C22: =Shortcuts!C24 -> Ctrl + Shift + r | K22: =K21+1 -> 19 | L22: =CONCATENATE("Order ",K22) -> Order 19 | M22: 13 | N22: =M22*$R$4 -> 16.25 | O22: 0.18 | P22: =N22+(N22*O22) -> 19.175
A23: =Shortcuts!A25 -> Apply bottom border | B23: =Shortcuts!B25 -> Option + Shift + 3 | C23: =Shortcuts!C25 -> Alt + Shift + 3 | K23: =K22+1 -> 20 | L23: =CONCATENATE("Order ",K23) -> Order 20 | M23: 11 | N23: =M23*$R$4 -> 13.75 | O23: 0.18 | P23: =N23+(N23*O23) -> 16.225
A24: =Shortcuts!A26 -> Apply outer border | B24: =left(Shortcuts!B26,18) -> Option + Shift + 7 | C24: =left(Shortcuts!C26,15) -> Alt + Shift + 7 | K24: =K23+1 -> 21 | L24: =CONCATENATE("Order ",K24) -> Order 21 | M24: 6 | N24: =M24*$R$4 -> 7.5 | O24: 0.15 | P24: =N24+(N24*O24) -> 8.625
A25: =Shortcuts!A27 -> Remove borders | B25: =Shortcuts!B27 -> Option + Shift + 6 | C25: =Shortcuts!C27 -> Alt + Shift + 6 | K25: =K24+1 -> 22 | L25: =CONCATENATE("Order ",K25) -> Order 22 | M25: 12 | N25: =M25*$R$4 -> 15 | O25: 0.15 | P25: =N25+(N25*O25) -> 17.25
A26: =Shortcuts!A28 -> Insert link | B26: =Shortcuts!B28 -> ⌘ + k | C26: =Shortcuts!C28 -> Ctrl + k | K26: =K25+1 -> 23 | L26: =CONCATENATE("Order ",K26) -> Order 23 | M26: 4 | N26: =M26*$R$4 -> 5 | O26: 0.15 | P26: =N26+(N26*O26) -> 5.75
A27: =Shortcuts!A29 -> Format as decimal | B27: =Shortcuts!B29 -> Ctrl + Shift + 1 | C27: =Shortcuts!C29 -> Ctrl + Shift + 1 | K27: =K26+1 -> 24 | L27: =CONCATENATE("Order ",K27) -> Order 24 | M27: 9 | N27: =M27*$R$4 -> 11.25 | O27: 0.15 | P27: =N27+(N27*O27) -> 12.9375
A28: =Shortcuts!A30 -> Format as time | B28: =Shortcuts!B30 -> Ctrl + Shift + 2 | C28: =Shortcuts!C30 -> Ctrl + Shift + 2 | K28: =K27+1 -> 25 | L28: =CONCATENATE("Order ",K28) -> Order 25 | M28: 16 | N28: =M28*$R$4 -> 20 | O28: 0.15 | P28: =N28+(N28*O28) -> 23
A29: =Shortcuts!A31 -> Format as date | B29: =Shortcuts!B31 -> Ctrl + Shift + 3 | C29: =Shortcuts!C31 -> Ctrl + Shift + 3 | K29: =K28+1 -> 26 | L29: =CONCATENATE("Order ",K29) -> Order 26 | M29: 14 | N29: =M29*$R$4 -> 17.5 | O29: 0.15 | P29: =N29+(N29*O29) -> 20.125
A30: =Shortcuts!A32 -> Format as currency | B30: =Shortcuts!B32 -> Ctrl + Shift + 4 | C30: =Shortcuts!C32 -> Ctrl + Shift + 4 | K30: =K29+1 -> 27 | L30: =CONCATENATE("Order ",K30) -> Order 27 | M30: 5 | N30: =M30*$R$4 -> 6.25 | O30: 0.18 | P30: =N30+(N30*O30) -> 7.375
A31: =Shortcuts!A33 -> Format as percentage | B31: =Shortcuts!B33 -> Ctrl + Shift + 5 | C31: =Shortcuts!C33 -> Ctrl + Shift + 5 | K31: =K30+1 -> 28 | L31: =CONCATENATE("Order ",K31) -> Order 28 | M31: 8 | N31: =M31*$R$4 -> 10 | O31: 0.18 | P31: =N31+(N31*O31) -> 11.8
A32: =Shortcuts!A34 -> Clear formatting | B32: =Shortcuts!B34 -> ⌘ + \ | C32: =Shortcuts!C34 -> Ctrl + \ | K32: =K31+1 -> 29 | L32: =CONCATENATE("Order ",K32) -> Order 29 | M32: 5 | N32: =M32*$R$4 -> 6.25 | O32: 0.15 | P32: =N32+(N32*O32) -> 7.1875
A33: =Shortcuts!A35 -> Display list of sheets | B33: =Shortcuts!B35 -> Option + Shift + k | C33: =Shortcuts!C35 -> Alt + Shift + k | K33: =K32+1 -> 30 | L33: =CONCATENATE("Order ",K33) -> Order 30 | M33: 19 | N33: =M33*$R$4 -> 23.75 | O33: 0.15 | P33: =N33+(N33*O33) -> 27.3125
A34: =Shortcuts!A36 -> Group rows or columns | B34: =Shortcuts!B36 -> Option + Shift + Right arrow | C34: =Shortcuts!C36 -> Ctrl + Shift + 9 | K34: =K33+1 -> 31 | L34: =CONCATENATE("Order ",K34) -> Order 31 | M34: 17 | N34: =M34*$R$4 -> 21.25 | O34: 0.18 | P34: =N34+(N34*O34) -> 25.075
A35: =Shortcuts!A37 -> Ungroup rows or columns | B35: =Shortcuts!B37 -> Option + Shift + Left arrow | C35: =Shortcuts!C37 -> Ctrl + Shift + 0 | K35: =K34+1 -> 32 | L35: =CONCATENATE("Order ",K35) -> Order 32 | M35: 15 | N35: =M35*$R$4 -> 18.75 | O35: 0.15 | P35: =N35+(N35*O35) -> 21.5625
A36: Cut | B36: ⌘ + x | C36: Ctrl + x | K36: =K35+1 -> 33 | L36: =CONCATENATE("Order ",K36) -> Order 33 | M36: 17 | N36: =M36*$R$4 -> 21.25 | O36: 0.18 | P36: =N36+(N36*O36) -> 25.075
A37: Copy | B37: ⌘ + c | C37: Ctrl + c | K37: =K36+1 -> 34 | L37: =CONCATENATE("Order ",K37) -> Order 34 | M37: 11 | N37: =M37*$R$4 -> 13.75 | O37: 0.15 | P37: =N37+(N37*O37) -> 15.8125
K38: =K37+1 -> 35 | L38: =CONCATENATE("Order ",K38) -> Order 35 | M38: 15 | N38: =M38*$R$4 -> 18.75 | O38: 0.15 | P38: =N38+(N38*O38) -> 21.5625
K39: =K38+1 -> 36 | L39: =CONCATENATE("Order ",K39) -> Order 36 | M39: 10 | N39: =M39*$R$4 -> 12.5 | O39: 0.15 | P39: =N39+(N39*O39) -> 14.375
K40: =K39+1 -> 37 | L40: =CONCATENATE("Order ",K40) -> Order 37 | M40: 9 | N40: =M40*$R$4 -> 11.25 | O40: 0.18 | P40: =N40+(N40*O40) -> 13.275
...

Sheet Lecture Four Formatting your Sp
A1: Index | B1: Order | C1: # of Dumplings | D1: Cost | E1: Tip | F1: Total
A2: 1 | B2: Order 1 | C2: 19 | D2: 23.75 | E2: 0.18 | F2: 28.025
A3: 2 | B3: Order 2 | C3: 13 | D3: 16.25 | E3: 0.18 | F3: 19.175
A4: 3 | B4: Order 3 | C4: 19 | D4: 23.75 | E4: 0.15 | F4: 27.3125
A5: 4 | B5: Order 4 | C5: 18 | D5: 22.5 | E5: 0.18 | F5: 26.55
A6: 5 | B6: Order 5 | C6: 16 | D6: 20 | E6: 0.18 | F6: 23.6
A7: 6 | B7: Order 6 | C7: 18 | D7: 22.5 | E7: 0.15 | F7: 25.875
A8: 7 | B8: Order 7 | C8: 13 | D8: 16.25 | E8: 0.18 | F8: 19.175
A9: 8 | B9: Order 8 | C9: 12 | D9: 15 | E9: 0.18 | F9: 17.7
A10: 9 | B10: Order 9 | C10: 7 | D10: 8.75 | E10: 0.15 | F10: 10.0625
A11: 10 | B11: Order 10 | C11: 8 | D11: 10 | E11: 0.15 | F11: 11.5
A12: 11 | B12: Order 11 | C12: 7 | D12: 8.75 | E12: 0.15 | F12: 10.0625
A13: 12 | B13: Order 12 | C13: 5 | D13: 6.25 | E13: 0.15 | F13: 7.1875
... A101: 100 | B101: Order 100 | C101: 19 | D101: 23.75 | E101: 0.15 | F101: 27.3125
